<?xml version="1.0" ?>
<!-- =================================================================================== -->
<!-- |    This document was autogenerated by xacro from arm.xacro                      | -->
<!-- |    EDITING THIS FILE BY HAND IS NOT RECOMMENDED                                 | -->
<!-- =================================================================================== -->
<robot name="mrm" xmlns:xacro="http://www.ros.org/wiki/xacro">
  <!-- END - Include -->
  <link name="base_link">
    <inertial>
      <mass value="1024"/>
      <origin rpy="0 0 0" xyz="0 0 0.0675"/>
      <inertia ixx="170.667" ixy="0" ixz="0" iyy="170.667" iyz="0" izz="170.667"/>
    </inertial>
    <collision>
      <origin rpy="0 0 0" xyz="0 0 0.0675"/>
      <geometry>
        <box size="0.09 0.09 0.135"/>
      </geometry>
    </collision>
    <visual>
      <origin rpy="0 0 0" xyz="0 0 0.0675"/>
      <geometry>
        <box size="0.09 0.09 0.135"/>
      </geometry>
    </visual>
  </link>
  <link name="link_01">
    <inertial>
      <mass value="0.01"/>
      <origin rpy="0 0 0" xyz="0 0 0.0145"/>
      <inertia ixx="1.0" ixy="0" ixz="0" iyy="1.0" iyz="0" izz="1.0"/>
    </inertial>
    <collision>
      <origin rpy="0 0 0" xyz="0 0 0.0145"/>
      <geometry>
        <cylinder length="0.029" radius="0.02"/>
      </geometry>
    </collision>
    <visual>
      <origin rpy="0 0 0" xyz="0 0 0.0145"/>
      <geometry>
        <cylinder length="0.029" radius="0.02"/>
      </geometry>
    </visual>
  </link>
  <link name="link_02">
    <inertial>
      <mass value="0.1"/>
      <origin rpy="0 0 0" xyz="0.0515 0 0"/>
      <inertia ixx="0.1" ixy="0" ixz="0" iyy="0.1" iyz="0" izz="0.1"/>
    </inertial>
    <collision>
      <origin rpy="0 0 0" xyz="0.0515 0 0"/>
      <geometry>
        <box size="0.103 0.052 0.025"/>
      </geometry>
    </collision>
    <visual>
      <origin rpy="0 0 0" xyz="0.0515 0 0"/>
      <geometry>
        <box size="0.103 0.052 0.025"/>
      </geometry>
    </visual>
  </link>
  <link name="link_03">
    <inertial>
      <mass value="0.1"/>
      <origin rpy="0 0 0" xyz="0.0325 0 0"/>
      <inertia ixx="0.1" ixy="0" ixz="0" iyy="0.1" iyz="0" izz="0.1"/>
    </inertial>
    <collision>
      <origin rpy="0 0 0" xyz="0.0325 0 0"/>
      <geometry>
        <box size="0.065 0.022 0.055"/>
      </geometry>
    </collision>
    <visual>
      <origin rpy="0 0 0" xyz="0.0325 0 0"/>
      <geometry>
        <box size="0.065 0.022 0.055"/>
      </geometry>
    </visual>
  </link>
  <link name="link_04">
    <inertial>
      <mass value="0.1"/>
      <origin rpy="0 0 0" xyz="0.0275 0 0"/>
      <inertia ixx="0.1" ixy="0" ixz="0" iyy="0.1" iyz="0" izz="0.1"/>
    </inertial>
    <collision>
      <origin rpy="0 0 0" xyz="0.0275 0 0"/>
      <geometry>
        <box size="0.055 0.052 0.025"/>
      </geometry>
    </collision>
    <visual>
      <origin rpy="0 0 0" xyz="0.0275 0 0"/>
      <geometry>
        <box size="0.055 0.052 0.025"/>
      </geometry>
    </visual>
  </link>
  <link name="ir_ranger">
    <inertial>
      <mass value="0.1"/>
      <origin rpy="0 0 0" xyz="0.015 0 0"/>
      <inertia ixx="0.1" ixy="0" ixz="0" iyy="0.1" iyz="0" izz="0.1"/>
    </inertial>
    <collision>
      <origin rpy="0 0 0" xyz="0.015 0 0"/>
      <geometry>
        <box size="0.03 0.03 0.005"/>
      </geometry>
    </collision>
    <visual>
      <origin rpy="0 0 0" xyz="0.015 0 0"/>
      <geometry>
        <box size="0.03 0.03 0.005"/>
      </geometry>
    </visual>
  </link>
  <link name="link_clawR">
    <inertial>
      <mass value="0.1"/>
      <origin rpy="0 0 0" xyz="-0.03 -0.014 -0.005"/>
      <inertia ixx="0.1" ixy="0" ixz="0" iyy="0.1" iyz="0" izz="0.1"/>
    </inertial>
    <collision>
      <origin rpy="0 0 0" xyz="-0.03 -0.014 -0.005"/>
      <geometry>
        <mesh filename="package://arm-model/meshes/gripperRight.stl" scale="0.001 0.001 0.001"/>
      </geometry>
    </collision>
    <visual>
      <origin rpy="0 0 0" xyz="-0.03 -0.014 -0.005"/>
      <geometry>
        <mesh filename="package://arm-model/meshes/gripperRight.stl" scale="0.001 0.001 0.001"/>
      </geometry>
      <!-- <material name="light_black"/> -->
    </visual>
  </link>
  <link name="link_clawL">
    <inertial>
      <mass value="0.1"/>
      <origin rpy="0 0 0" xyz="-0.03 0.014 -0.005"/>
      <inertia ixx="0.1" ixy="0" ixz="0" iyy="0.1" iyz="0" izz="0.1"/>
    </inertial>
    <collision>
      <origin rpy="0 0 0" xyz="-0.03 0.014 -0.005"/>
      <geometry>
        <mesh filename="package://arm-model/meshes/gripperLeft.stl" scale="0.001 0.001 0.001"/>
      </geometry>
    </collision>
    <visual>
      <origin rpy="0 0 0" xyz="-0.03 0.014 -0.005"/>
      <geometry>
        <mesh filename="package://arm-model/meshes/gripperLeft.stl" scale="0.001 0.001 0.001"/>
      </geometry>
      <!-- <material name="light_black"/> -->
    </visual>
  </link>
  <joint name="base_link__link_01" type="revolute">
    <axis xyz="0 0 -1"/>
    <limit effort="1000" lower="-1.5708" upper="1.5708" velocity="0.5"/>
    <origin rpy="0 0 0" xyz="0 0 0.135"/>
    <parent link="base_link"/>
    <child link="link_01"/>
    <dynamics damping="10.0" friction="10.0"/>
  </joint>
  <joint name="link_01__link_02" type="revolute">
    <axis xyz="0 -1 0"/>
    <limit effort="1000" lower="-0.7854" upper="0.7854" velocity="0.5"/>
    <origin rpy="0 -0.698 0" xyz="0 0 0.029"/>
    <parent link="link_01"/>
    <child link="link_02"/>
    <dynamics damping="10.0" friction="10.0"/>
  </joint>
  <joint name="link_02__link_03" type="revolute">
    <axis xyz="0 -1 0"/>
    <limit effort="1000" lower="-1.5708" upper="1.5708" velocity="0.5"/>
    <origin rpy="0 0.5584 0" xyz="0.103 0 0.015"/>
    <parent link="link_02"/>
    <child link="link_03"/>
    <dynamics damping="10.0" friction="10.0"/>
  </joint>
  <joint name="link_03__link_04" type="revolute">
    <axis xyz="0 -1 0"/>
    <limit effort="1000" lower="-1.5708" upper="1.5708" velocity="0.5"/>
    <origin rpy="0 1.047 0" xyz="0.065 0 -0.015"/>
    <parent link="link_03"/>
    <child link="link_04"/>
    <dynamics damping="10.0" friction="10.0"/>
  </joint>
  <joint name="link_04__ir_ranger" type="fixed">
    <origin rpy="0 0 0" xyz="0.055 0 0"/>
    <parent link="link_04"/>
    <child link="ir_ranger"/>
  </joint>
  <joint name="ir_ranger__link_clawL" type="revolute">
    <axis xyz="0 0 -1"/>
    <limit effort="1000" lower="-0.6" upper="0.9" velocity="0.5"/>
    <origin rpy="0 0 0" xyz="0.03 -0.014  -0.00"/>
    <parent link="ir_ranger"/>
    <child link="link_clawL"/>
    <dynamics damping="10.0" friction="10.0"/>
  </joint>
  <joint name="ir_ranger__link_clawR" type="revolute">
    <axis xyz="0 0 1"/>
    <limit effort="1000" lower="-0.6" upper="0.9" velocity="0.5"/>
    <origin rpy="0 0 0" xyz="0.03 +0.014  -0.00"/>
    <parent link="ir_ranger"/>
    <child link="link_clawR"/>
    <dynamics damping="10.0" friction="10.0"/>
  </joint>
  <!-- END - Robot description Total weight = 1373.401  ==> 13473.065N-->
  <!-- This plugin will publish the joint_states for the selected joints 
            (which robot_state_publisher can then use to broadcast the approprate tf). -->
  <gazebo>
    <plugin filename="libgazebo_ros_joint_state_publisher.so" name="gazebo_ros_joint_state_publisher">
      <update_rate>20</update_rate>
      <joint_name>base_link__link_01</joint_name>
      <joint_name>link_01__link_02</joint_name>
      <joint_name>link_03__link_04</joint_name>
    </plugin>
  </gazebo>
  <!-- This plugin will read a JointTrajectory message from the /set_joint_trajectory topic 
            and move the machine accordingly. It's a bit clunky but it works. -->
  <!-- You'll probably want to add damping to the joints to stop them it flopping around. 
            e.g. <dynamics damping="10.0" friction="10.0"/> -->
  <!-- Here's an example message to publish to test it:
            ros2 topic pub -1 /set_joint_trajectory trajectory_msgs/msg/JointTrajectory  '{header: {frame_id: world}, joint_names: [slider_joint, arm_joint], points: [  {positions: {0.8,0.6}} ]}' 
            ros2 topic pub -1 /set_joint_trajectory trajectory_msgs/msg/JointTrajectory  '{header: {frame_id: world}, joint_names: [base_link__link_01], points: [  {positions: {1.8}} ]}'
            -->
  <gazebo>
    <plugin filename="libgazebo_ros_joint_pose_trajectory.so" name="gazebo_ros_joint_pose_trajectory">
      <update_rate>2</update_rate>
    </plugin>
  </gazebo>
</robot>

