<?xml version="1.0" ?>
<robot xmlns:xacro="http://www.ros.org/wiki/xacro">

  <xacro:macro name="m_joint" params="name type axis_xyz origin_rpy origin_xyz parent child limit_e limit_l limit_u limit_v">
    <joint name="${name}" type="${type}">
      <axis xyz="${axis_xyz}" />
      <limit effort="${limit_e}" lower="${limit_l}" upper="${limit_u}" velocity="${limit_v}" />
      <origin rpy="${origin_rpy}" xyz="${origin_xyz}" />
      <parent link="${parent}" />
      <child link="${child}" />
      <dynamics damping="10.0" friction="10.0"/>
    </joint>
  </xacro:macro>

  <xacro:macro name="m_axis" params="name axis_xyz origin_rpy origin_xyz parent child">
    <joint name="${name}" type="continuous">
      <axis xyz="${axis_xyz}" />
      <origin rpy="${origin_rpy}" xyz="${origin_xyz}" />
      <parent link="${parent}" />
      <child link="${child}" />
    </joint>
  </xacro:macro>


  <xacro:macro name="m_link_cylinder" params="name origin_xyz origin_rpy radius length mass ixx ixy ixz iyy iyz izz material">
    <link name="${name}">
      <inertial>
        <mass value="${mass}" />
        <origin rpy="${origin_rpy}" xyz="${origin_xyz}" />
        <inertia ixx="${ixx}" ixy="${ixy}" ixz="${ixz}" iyy="${iyy}" iyz="${iyz}" izz="${izz}" />
      </inertial>
      <collision>
        <origin rpy="${origin_rpy}" xyz="${origin_xyz}" />
        <geometry>
          <cylinder radius="${radius}" length="${length}" />
        </geometry>
      </collision>
      <visual>
        <origin rpy="${origin_rpy}" xyz="${origin_xyz}" />
        <geometry>
          <cylinder radius="${radius}" length="${length}" />
        </geometry>
        <material name="${material}"/>
      </visual>
    </link>
  </xacro:macro>

  <xacro:macro name="m_link_box" params="name origin_xyz origin_rpy size mass ixx ixy ixz iyy iyz izz material">
    <link name="${name}">
      <inertial>
        <mass value="${mass}" />
        <origin rpy="${origin_rpy}" xyz="${origin_xyz}" />
        <inertia ixx="${ixx}" ixy="${ixy}" ixz="${ixz}" iyy="${iyy}" iyz="${iyz}" izz="${izz}" />
      </inertial>
      <collision>
        <origin rpy="${origin_rpy}" xyz="${origin_xyz}" />
        <geometry>
          <box size="${size}" />
        </geometry>
      </collision>
      <visual>
        <origin rpy="${origin_rpy}" xyz="${origin_xyz}" />
        <geometry>
          <box size="${size}" />
        </geometry>
        <material name="${material}"/>
      </visual>
    </link>
  </xacro:macro>

  <xacro:macro name="m_link_mesh" params="name origin_xyz origin_rpy meshfile meshscale mass ixx ixy ixz iyy iyz izz">
    <link name="${name}">
      <inertial>
        <mass value="${mass}" />
        <origin rpy="${origin_rpy}" xyz="${origin_xyz}" />
        <inertia ixx="${ixx}" ixy="${ixy}" ixz="${ixz}" iyy="${iyy}" iyz="${iyz}" izz="${izz}" />
      </inertial>
      <collision>
        <origin rpy="${origin_rpy}" xyz="${origin_xyz}" />
        <geometry>
          <mesh filename="${meshfile}" scale="${meshscale}"/>
        </geometry>
      </collision>
      <visual>
        <origin rpy="${origin_rpy}" xyz="${origin_xyz}" />
        <geometry>
          <mesh filename="${meshfile}" scale="${meshscale}"/>
        </geometry>
        <material name="light_black"/>
      </visual>
    </link>
  </xacro:macro>

</robot>