<?xml version="1.0" ?>
<!-- =================================================================================== -->
<!-- |    This document was autogenerated by xacro from arm.xacro                      | -->
<!-- |    EDITING THIS FILE BY HAND IS NOT RECOMMENDED                                 | -->
<!-- =================================================================================== -->
<robot name="mrm">
  <!-- END - Include -->
  <link name="base_link">
    <inertial>
      <mass value="1024"/>
      <origin rpy="0 0 0" xyz="0 0 0"/>
      <inertia ixx="170.667" ixy="0" ixz="0" iyy="170.667" iyz="0" izz="170.667"/>
    </inertial>
    <collision>
      <origin rpy="0 0 0" xyz="0 0 0"/>
      <geometry>
        <box size="1 1 1"/>
      </geometry>
    </collision>
    <visual>
      <origin rpy="0 0 0" xyz="0 0 0"/>
      <geometry>
        <box size="1 1 1"/>
      </geometry>
    </visual>
  </link>
  <joint name="base_link__link_01" type="revolute">
    <axis xyz="0 0 1"/>
    <limit effort="1000" lower="-3.14" upper="3.14" velocity="0.5"/>
    <origin rpy="0 0 0" xyz="0 0 0.5"/>
    <parent link="base_link"/>
    <child link="link_01"/>
  </joint>
  <transmission name="trans_base_link__link_01">
    <type>transmission_interface/SimpleTransmission</type>
    <joint name="base_link__link_01">
      <hardwareInterface>hardware_interface/EffortJointInterface</hardwareInterface>
    </joint>
    <actuator name="motor_base_link__link_01">
      <hardwareInterface>hardware_interface/EffortJointInterface</hardwareInterface>
      <mechanicalReduction>1</mechanicalReduction>
    </actuator>
  </transmission>
  <!-- <m_link_mesh name="${link_01_name}"
              origin_rpy="0 0 0" origin_xyz="0 0 -0.1"
              mass="157.633"
              ixx="13.235" ixy="0" ixz="0"
              iyy="13.235" iyz="0"
              izz="9.655"
              meshfile="package://mrm_description/meshes/Link1-v2.stl"
              meshscale="0.001 0.001 0.001" /> -->
  <link name="link_01">
    <inertial>
      <mass value="157.633"/>
      <origin rpy="0 0 0" xyz="0 0 0.2"/>
      <inertia ixx="13.235" ixy="0" ixz="0" iyy="13.235" iyz="0" izz="9.655"/>
    </inertial>
    <collision>
      <origin rpy="0 0 0" xyz="0 0 0.2"/>
      <geometry>
        <cylinder length="0.4" radius="0.35"/>
      </geometry>
    </collision>
    <visual>
      <origin rpy="0 0 0" xyz="0 0 0.2"/>
      <geometry>
        <cylinder length="0.4" radius="0.35"/>
      </geometry>
    </visual>
  </link>
  <joint name="link_01__link_02" type="revolute">
    <axis xyz="0 1 0"/>
    <limit effort="1000" lower="0" upper="0.5" velocity="0.5"/>
    <origin rpy="0 0 0" xyz="0 0 0.4"/>
    <parent link="link_01"/>
    <child link="link_02"/>
  </joint>
  <transmission name="trans_link_01__link_02">
    <type>transmission_interface/SimpleTransmission</type>
    <joint name="link_01__link_02">
      <hardwareInterface>hardware_interface/EffortJointInterface</hardwareInterface>
    </joint>
    <actuator name="motor_link_01__link_02">
      <hardwareInterface>hardware_interface/EffortJointInterface</hardwareInterface>
      <mechanicalReduction>1</mechanicalReduction>
    </actuator>
  </transmission>
  <link name="link_02">
    <inertial>
      <mass value="57.906"/>
      <origin rpy="0 0 0" xyz="0 0 0.4"/>
      <inertia ixx="12.679" ixy="0" ixz="0" iyy="12.679" iyz="0" izz="0.651"/>
    </inertial>
    <collision>
      <origin rpy="0 0 0" xyz="0 0 0.4"/>
      <geometry>
        <cylinder length="0.8" radius="0.15"/>
      </geometry>
    </collision>
    <visual>
      <origin rpy="0 0 0" xyz="0 0 0.4"/>
      <geometry>
        <cylinder length="0.8" radius="0.15"/>
      </geometry>
    </visual>
  </link>
  <joint name="link_02__link_03" type="revolute">
    <axis xyz="0 1 0"/>
    <limit effort="1000" lower="0" upper="0.75" velocity="0.5"/>
    <origin rpy="0 0 0" xyz="0 0 0.8"/>
    <parent link="link_02"/>
    <child link="link_03"/>
  </joint>
  <transmission name="trans_link_02__link_03">
    <type>transmission_interface/SimpleTransmission</type>
    <joint name="link_02__link_03">
      <hardwareInterface>hardware_interface/EffortJointInterface</hardwareInterface>
    </joint>
    <actuator name="motor_link_02__link_03">
      <hardwareInterface>hardware_interface/EffortJointInterface</hardwareInterface>
      <mechanicalReduction>1</mechanicalReduction>
    </actuator>
  </transmission>
  <link name="link_03">
    <inertial>
      <mass value="57.906"/>
      <origin rpy="0 0 0" xyz="0 0 0.4"/>
      <inertia ixx="12.679" ixy="0" ixz="0" iyy="12.679" iyz="0" izz="0.651"/>
    </inertial>
    <collision>
      <origin rpy="0 0 0" xyz="0 0 0.4"/>
      <geometry>
        <cylinder length="0.8" radius="0.15"/>
      </geometry>
    </collision>
    <visual>
      <origin rpy="0 0 0" xyz="0 0 0.4"/>
      <geometry>
        <cylinder length="0.8" radius="0.15"/>
      </geometry>
    </visual>
  </link>
  <joint name="link_03__link_04" type="revolute">
    <axis xyz="0 1 0"/>
    <limit effort="1000" lower="0" upper="0.75" velocity="0.5"/>
    <origin rpy="0 0 0" xyz="0 0 0.8"/>
    <parent link="link_03"/>
    <child link="link_04"/>
  </joint>
  <transmission name="trans_link_03__link_04">
    <type>transmission_interface/SimpleTransmission</type>
    <joint name="link_03__link_04">
      <hardwareInterface>hardware_interface/EffortJointInterface</hardwareInterface>
    </joint>
    <actuator name="motor_link_03__link_04">
      <hardwareInterface>hardware_interface/EffortJointInterface</hardwareInterface>
      <mechanicalReduction>1</mechanicalReduction>
    </actuator>
  </transmission>
  <link name="link_04">
    <inertial>
      <mass value="57.906"/>
      <origin rpy="0 0 0" xyz="0 0 0.4"/>
      <inertia ixx="12.679" ixy="0" ixz="0" iyy="12.679" iyz="0" izz="0.651"/>
    </inertial>
    <collision>
      <origin rpy="0 0 0" xyz="0 0 0.4"/>
      <geometry>
        <cylinder length="0.8" radius="0.15"/>
      </geometry>
    </collision>
    <visual>
      <origin rpy="0 0 0" xyz="0 0 0.4"/>
      <geometry>
        <cylinder length="0.8" radius="0.15"/>
      </geometry>
    </visual>
  </link>
  <joint name="link_04__link_05" type="revolute">
    <axis xyz="0 0 1"/>
    <limit effort="1000" lower="-3.14" upper="3.14" velocity="0.5"/>
    <origin rpy="0 0 0" xyz="0 0 0.8"/>
    <parent link="link_04"/>
    <child link="link_05"/>
  </joint>
  <transmission name="trans_link_04__link_05">
    <type>transmission_interface/SimpleTransmission</type>
    <joint name="link_04__link_05">
      <hardwareInterface>hardware_interface/EffortJointInterface</hardwareInterface>
    </joint>
    <actuator name="motor_link_04__link_05">
      <hardwareInterface>hardware_interface/EffortJointInterface</hardwareInterface>
      <mechanicalReduction>1</mechanicalReduction>
    </actuator>
  </transmission>
  <link name="link_05">
    <inertial>
      <mass value="18.056"/>
      <origin rpy="0 0 0" xyz="0 0 0.125"/>
      <inertia ixx="0.479" ixy="0" ixz="0" iyy="0.479" iyz="0" izz="0.204"/>
    </inertial>
    <collision>
      <origin rpy="0 0 0" xyz="0 0 0.125"/>
      <geometry>
        <cylinder length="0.25" radius="0.15"/>
      </geometry>
    </collision>
    <visual>
      <origin rpy="0 0 0" xyz="0 0 0.125"/>
      <geometry>
        <cylinder length="0.25" radius="0.15"/>
      </geometry>
    </visual>
  </link>
  <!-- END - Robot description -->
  <gazebo>
    <plugin filename="libgazebo_ros_control.so" name="gazebo_ros_control">
      
    </plugin>
  </gazebo>


    <!-- This plugin will publish the joint_states for the selected joints 
            (which robot_state_publisher can then use to broadcast the approprate tf). -->
 
  <gazebo>
      <plugin name="gazebo_ros_joint_state_publisher"
          filename="libgazebo_ros_joint_state_publisher.so">
          <update_rate>20</update_rate>
          <joint_name>slider_joint</joint_name>
          <joint_name>arm_joint</joint_name>
      </plugin>
  </gazebo>

    <!-- This plugin will read a JointTrajectory message from the /set_joint_trajectory topic 
            and move the machine accordingly. It's a bit clunky but it works. -->
    <!-- You'll probably want to add damping to the joints to stop them it flopping around. 
            e.g. <dynamics damping="10.0" friction="10.0"/> -->
    <!-- Here's an example message to publish to test it:
            ros2 topic pub -1 /set_joint_trajectory trajectory_msgs/msg/JointTrajectory  '{header: {frame_id: world}, joint_names: [slider_joint, arm_joint], points: [  {positions: {0.8,0.6}} ]}' -->
    <gazebo>
        <plugin name="gazebo_ros_joint_pose_trajectory"
            filename="libgazebo_ros_joint_pose_trajectory.so">
            <update_rate>2</update_rate>
        </plugin>
    </gazebo>

</robot>
